
The following have been reloaded with a version change:
  1) python/3.7.4 => python/3.8.2

Starting training efficientnet-b0 with args --version=b0 --pretrain --elastic-scale=0.2 --elastic-trans=0.3 --elastic-shear=0.15 --elastic-degree=10 --batch-size=128 --max-epochs=3000 --lr-schedule=cyclic --cyclic-mode=gamma --cyclic-max=1e-1 --cyclic-base=1e-3 --cyclic-f=60 at Mon Mar 15 19:06:20 UTC 2021.
TensorFlow installation not found - running with reduced feature set.
TensorBoard 2.4.1 at http://0.0.0.0:6006/ (Press CTRL+C to quit)
GPU available: True, used: True
TPU available: None, using: 0 TPU cores
Set SLURM handle signals.

  | Name  | Type              | Params
--------------------------------------------
0 | model | CovidEfficientNet | 4.0 M 
--------------------------------------------
4.0 M     Trainable params
0         Non-trainable params
4.0 M     Total params
16.033    Total estimated model params size (MB)
Loaded pretrained weights for efficientnet-b0
Exception ignored in: <function _releaseLock at 0x7fefef5e6f70>
Traceback (most recent call last):
  File "/cvmfs/soft.computecanada.ca/easybuild/software/2017/Core/python/3.8.2/lib/python3.8/logging/__init__.py", line 223, in _releaseLock
    def _releaseLock():
KeyboardInterrupt: 
Traceback (most recent call last):
  File "/gpfs/project/6005889/dberger/error-consistency/.venv/lib/python3.8/site-packages/torch/utils/data/dataloader.py", line 872, in _try_get_data
    data = self._data_queue.get(timeout=timeout)
  File "/cvmfs/soft.computecanada.ca/easybuild/software/2017/Core/python/3.8.2/lib/python3.8/queue.py", line 178, in get
    raise Empty
_queue.Empty

The above exception was the direct cause of the following exception:

Traceback (most recent call last):
  File "/home/dberger/projects/def-jlevman/dberger/error-consistency/analysis/covid/efficientnet.py", line 309, in <module>
    trainer.fit(model, datamodule=dm)
  File "/gpfs/project/6005889/dberger/error-consistency/.venv/lib/python3.8/site-packages/pytorch_lightning/trainer/trainer.py", line 513, in fit
    self.dispatch()
  File "/gpfs/project/6005889/dberger/error-consistency/.venv/lib/python3.8/site-packages/pytorch_lightning/trainer/trainer.py", line 553, in dispatch
    self.accelerator.start_training(self)
  File "/gpfs/project/6005889/dberger/error-consistency/.venv/lib/python3.8/site-packages/pytorch_lightning/accelerators/accelerator.py", line 74, in start_training
    self.training_type_plugin.start_training(trainer)
  File "/gpfs/project/6005889/dberger/error-consistency/.venv/lib/python3.8/site-packages/pytorch_lightning/plugins/training_type/training_type_plugin.py", line 111, in start_training
    self._results = trainer.run_train()
  File "/gpfs/project/6005889/dberger/error-consistency/.venv/lib/python3.8/site-packages/pytorch_lightning/trainer/trainer.py", line 644, in run_train
    self.train_loop.run_training_epoch()
  File "/gpfs/project/6005889/dberger/error-consistency/.venv/lib/python3.8/site-packages/pytorch_lightning/trainer/training_loop.py", line 564, in run_training_epoch
    self.trainer.run_evaluation(on_epoch=True)
  File "/gpfs/project/6005889/dberger/error-consistency/.venv/lib/python3.8/site-packages/pytorch_lightning/trainer/trainer.py", line 719, in run_evaluation
    for batch_idx, batch in enumerate(dataloader):
  File "/gpfs/project/6005889/dberger/error-consistency/.venv/lib/python3.8/site-packages/torch/utils/data/dataloader.py", line 435, in __next__
    data = self._next_data()
  File "/gpfs/project/6005889/dberger/error-consistency/.venv/lib/python3.8/site-packages/torch/utils/data/dataloader.py", line 1068, in _next_data
    idx, data = self._get_data()
  File "/gpfs/project/6005889/dberger/error-consistency/.venv/lib/python3.8/site-packages/torch/utils/data/dataloader.py", line 1024, in _get_data
    success, data = self._try_get_data()
  File "/gpfs/project/6005889/dberger/error-consistency/.venv/lib/python3.8/site-packages/torch/utils/data/dataloader.py", line 885, in _try_get_data
    raise RuntimeError('DataLoader worker (pid(s) {}) exited unexpectedly'.format(pids_str)) from e
RuntimeError: DataLoader worker (pid(s) 214247, 214248, 214249) exited unexpectedly
